<?xml version="1.0" ?>
<robot xmlns:xacro="http://ros.org/wiki/xacro" name="prius">
    <!--- Surface properties must come first? -->
    <gazebo reference="front_left_wheel">
        <mu1>0.9</mu1>
        <mu2>0.9</mu2>
        <minDepth>0.005</minDepth>
        <kp>1e8</kp>
    </gazebo>
    <gazebo reference="front_right_wheel">
        <mu1>0.9</mu1>
        <mu2>0.9</mu2>
        <minDepth>0.005</minDepth>
        <kp>1e8</kp>
    </gazebo>
    <gazebo reference="rear_left_wheel">
        <mu1>0.9</mu1>
        <mu2>0.9</mu2>
        <minDepth>0.005</minDepth>
        <kp>1e8</kp>
    </gazebo>
    <gazebo reference="rear_right_wheel">
        <mu1>0.9</mu1>
        <mu2>0.9</mu2>
        <minDepth>0.005</minDepth>
        <kp>1e8</kp>
    </gazebo>
    <link name="base_link">
        <inertial>
            <mass value="1" />
            <inertia ixx="0.001" ixy="0.0" ixz="0.0" iyy="0.001" iyz="0.0" izz="0.001" />
        </inertial>
    </link>
    <joint name="base_link_connection" type="fixed">
        <parent link="base_link" />
        <child link="chassis" />
        <origin xyz="1.45 0 0" rpy="0 0 1.57" />
        <axis xyz="1 0 0" />
    </joint>
    <link name="chassis">
        <visual>
            <origin xyz="0 0 0" rpy="0 0 0" />
            <geometry>
                <mesh filename="package://prius_description/meshes/hybrid_body.obj" scale="0.01 0.01 0.01" />
            </geometry>
        </visual>
        <collision name="chassis">
            <origin xyz="0.0 0.05 0.625" rpy="0 0 0" />
            <geometry>
                <box size="1.7526 2.1 0.95" />
            </geometry>
        </collision>
        <inertial>
            <mass value="1356.0" />
            <origin xyz="0 0 0.48" rpy="0 0 1.5708" />
            <inertia ixx="2581.13354740" ixy="0.0" ixz="0.0" iyy="591.30846112" iyz="0.0" izz="2681.95008628" />
        </inertial>
    </link>
    <link name="fl_axle">
        <inertial>
            <mass value="1" />
            <origin xyz="0 0 0" />
            <inertia ixx="0.004" ixy="0.0" ixz="0.0" iyy="0.004" iyz="0.0" izz="0.004" />
        </inertial>
    </link>
    <link name="fr_axle">
        <inertial>
            <mass value="1" />
            <origin xyz="0 0 0" />
            <inertia ixx="0.004" ixy="0.0" ixz="0.0" iyy="0.004" iyz="0.0" izz="0.004" />
        </inertial>
    </link>
    <link name="front_left_wheel">
        <inertial>
            <mass value="11" />
            <origin xyz="0 0 0" />
            <inertia ixx="0.58631238" ixy="0.0" ixz="0.0" iyy="0.33552910" iyz="0.0" izz="0.33552910" />
        </inertial>
        <collision name="front_left_wheel_collision">
            <geometry>
                <sphere radius="0.31265" />
            </geometry>
        </collision>
        <visual>
            <origin xyz="0 0 0" rpy="0 0 0" />
            <geometry>
                <mesh filename="package://prius_description/meshes/wheel.obj" scale="0.01 0.01 0.01" />
            </geometry>
        </visual>
    </link>
    <link name="front_right_wheel">
        <inertial>
            <mass value="11" />
            <origin xyz="0 0 0" />
            <inertia ixx="0.58631238" ixy="0.0" ixz="0.0" iyy="0.33552910" iyz="0.0" izz="0.33552910" />
        </inertial>
        <collision name="front_right_wheel_collision">
            <geometry>
                <sphere radius="0.31265" />
            </geometry>
        </collision>
        <visual>
            <origin xyz="0 0 0" rpy="0 0 0" />
            <geometry>
                <mesh filename="package://prius_description/meshes/wheel.obj" scale="0.01 0.01 0.01" />
            </geometry>
        </visual>
    </link>
    <link name="rear_left_wheel">
        <inertial>
            <mass value="11" />
            <origin xyz="0 0 0" />
            <inertia ixx="0.58631238" ixy="0.0" ixz="0.0" iyy="0.33552910" iyz="0.0" izz="0.33552910" />
        </inertial>
        <collision name="rear_left_wheel_collision">
            <geometry>
                <sphere radius="0.31265" />
            </geometry>
        </collision>
        <visual>
            <origin xyz="0 0 0" rpy="0 0 0" />
            <geometry>
                <mesh filename="package://prius_description/meshes/wheel.obj" scale="0.01 0.01 0.01" />
            </geometry>
        </visual>
    </link>
    <link name="rear_right_wheel">
        <inertial>
            <mass value="11" />
            <origin xyz="0 0 0" />
            <inertia ixx="0.58631238" ixy="0.0" ixz="0.0" iyy="0.33552910" iyz="0.0" izz="0.33552910" />
        </inertial>
        <collision name="rear_right_wheel_collision">
            <geometry>
                <sphere radius="0.31265" />
            </geometry>
        </collision>
        <visual>
            <origin xyz="0 0 0" rpy="0 0 0" />
            <geometry>
                <mesh filename="package://prius_description/meshes/wheel.obj" scale="0.01 0.01 0.01" />
            </geometry>
        </visual>
    </link>
    <link name="steering_wheel">
        <inertial>
            <mass value="1.0" />
            <inertia ixx="0.14583300" ixy="0.0" ixz="0.0" iyy="0.14583300" iyz="0.0" izz="0.125" />
        </inertial>
        <visual>
            <origin xyz="0 0 0" rpy="1.302101 0 0" />
            <geometry>
                <mesh filename="package://prius_description/meshes/steering_wheel.obj" scale="0.01 0.01 0.01" />
            </geometry>
        </visual>
    </link>
    <joint name="steering_joint" type="continuous">
        <origin xyz="0.357734 -0.627868 0.988243" rpy="-1.302101 0 0" />
        <parent link="chassis" />
        <child link="steering_wheel" />
        <axis xyz="0 0 1" />
        <limit lower="-7.85" upper="7.85" effort="10000000" velocity="1000000" />
    </joint>
    <joint name="front_left_steer_joint" type="continuous">
        <parent link="chassis" />
        <child link="fl_axle" />
        <origin xyz="0.767 -1.41 0.3" rpy="0 0 0" />
        <axis xyz="0 0 1" />
        <limit lower="-0.8727" upper="0.8727" effort="10000000" velocity="1000000" />
    </joint>
    <joint name="front_right_steer_joint" type="continuous">
        <parent link="chassis" />
        <child link="fr_axle" />
        <origin xyz="-0.767 -1.41 0.3" rpy="0 0 0" />
        <axis xyz="0 0 1" />
        <limit lower="-0.8727" upper="0.8727" effort="10000000" velocity="1000000" />
    </joint>
    <joint name="front_left_wheel_joint" type="continuous">
        <parent link="fl_axle" />
        <child link="front_left_wheel" />
        <origin xyz="0 0 0" rpy="0 0 0" />
        <axis xyz="1 0 0" />
    </joint>
    <joint name="front_right_wheel_joint" type="continuous">
        <parent link="fr_axle" />
        <child link="front_right_wheel" />
        <origin xyz="0 0 0" rpy="0 0 0" />
        <axis xyz="1 0 0" />
    </joint>
    <joint name="rear_left_wheel_joint" type="continuous">
        <parent link="chassis" />
        <child link="rear_left_wheel" />
        <origin xyz="0.793 1.45 0.3" rpy="0 0 0" />
        <axis xyz="1 0 0" />
    </joint>
    <joint name="rear_right_wheel_joint" type="continuous">
        <parent link="chassis" />
        <child link="rear_right_wheel" />
        <origin xyz="-0.793 1.45 0.3" rpy="0 0 0" />
        <axis xyz="1 0 0" />
    </joint>
    <!-- Sensor links and fixed joints -->
    <link name="an_device">
        <inertial>
            <mass value="0" />
            <inertia ixx="0.0" ixy="0.0" ixz="0.0" iyy="0.0" iyz="0.0" izz="0.0" />
        </inertial>
    </link>
    <joint name="an_device_joint" type="fixed">
        <parent link="chassis" />
        <child link="an_device" />
        <origin xyz="0.25 0 0.678" rpy="3.1415 0 -1.5708" />
    </joint>
    <link name="velodyne">
        <inertial>
            <mass value="1" />
            <inertia ixx="0.001" ixy="0.0" ixz="0.0" iyy="0.001" iyz="0.0" izz="0.001" />
        </inertial>
    </link>
    <joint name="center_laser_joint" type="fixed">
        <parent link="chassis" />
        <child link="velodyne" />
        <origin xyz="0 0.55 1.65" rpy="0 0 3.1503" />
    </joint>
    <gazebo reference="base_link_connection">
        <disableFixedJointLumping>true</disableFixedJointLumping>
    </gazebo>
    <link name="front_camera_link">
        <inertial>
            <mass value="1" />
            <inertia ixx="0.001" ixy="0.0" ixz="0.0" iyy="0.001" iyz="0.0" izz="0.001" />
        </inertial>
    </link>
    <joint name="front_camera_joint" type="fixed">
        <parent link="chassis" />
        <child link="front_camera_link" />
        <origin xyz="0 -0.4 1.4" rpy="0 0.05 -1.5707" />
    </joint>
    <link name="left_camera_link">
        <inertial>
            <mass value="1" />
            <inertia ixx="0.001" ixy="0.0" ixz="0.0" iyy="0.001" iyz="0.0" izz="0.001" />
        </inertial>
    </link>
    <joint name="left_camera_joint" type="fixed">
        <parent link="front_camera_link" />
        <child link="left_camera_link" />
        <origin xyz="0 0.2 0" rpy="0 0 0" />
    </joint>
    <!-- TODO:
    Give _optical suffix as per REP103. The link 'left' is not very descriptive for a camera.
    A general link name like this may conflict with other links.
    Keep in mind that this change will break things like rviz configuration files.
  -->
    <link name="left">
        <inertial>
            <mass value="1" />
            <inertia ixx="0.001" ixy="0.0" ixz="0.0" iyy="0.001" iyz="0.0" izz="0.001" />
        </inertial>
    </link>
    <joint name="left_joint" type="fixed">
        <parent link="left_camera_link" />
        <child link="left" />
        <origin xyz="0.018637 -0.053563 -0.099793" rpy="1.740599 -3.125582 1.570676" />
    </joint>
    <link name="right_camera_link">
        <inertial>
            <mass value="1" />
            <inertia ixx="0.001" ixy="0.0" ixz="0.0" iyy="0.001" iyz="0.0" izz="0.001" />
        </inertial>
    </link>
    <joint name="right_camera_joint" type="fixed">
        <parent link="front_camera_link" />
        <child link="right_camera_link" />
        <origin xyz="0 -0.2 0" rpy="0 0 0" />
    </joint>
    <link name="right">
        <inertial>
            <mass value="1" />
            <inertia ixx="0.001" ixy="0.0" ixz="0.0" iyy="0.001" iyz="0.0" izz="0.001" />
        </inertial>
    </link>
    <joint name="right_joint" type="fixed">
        <parent link="right_camera_link" />
        <child link="right" />
        <origin xyz="0 0 0" rpy="-1.435 0.000 -1.571" />
    </joint>
    <link name="front_center_right_sonar_link">
        <inertial>
            <mass value="1" />
            <inertia ixx="0.001" ixy="0.0" ixz="0.0" iyy="0.001" iyz="0.0" izz="0.001" />
        </inertial>
    </link>
    <joint name="front_center_right_sonar_joint" type="fixed">
        <parent link="chassis" />
        <child link="front_center_right_sonar_link" />
        <origin xyz="-0.128881 -2.008378 0.652787" rpy="3.118306 3.012198 1.589669" />
    </joint>
    <gazebo>
        <plugin name="pruis_hybrid_drive" filename="libPriusHybridPlugin.so">
            <chassis>chassis</chassis>
            <front_left_wheel>front_left_wheel_joint</front_left_wheel>
            <front_right_wheel>front_right_wheel_joint</front_right_wheel>
            <front_left_wheel_steering>front_left_steer_joint</front_left_wheel_steering>
            <front_right_wheel_steering>front_right_steer_joint</front_right_wheel_steering>
            <back_left_wheel>rear_left_wheel_joint</back_left_wheel>
            <back_right_wheel>rear_right_wheel_joint</back_right_wheel>
            <steering_wheel>steering_joint</steering_wheel>
            <chassis_aero_force_gain>0.63045</chassis_aero_force_gain>
            <front_torque>859.4004393000001</front_torque>
            <back_torque>0</back_torque>
            <front_brake_torque>1031.28052716</front_brake_torque>
            <back_brake_torque>687.5203514400001</back_brake_torque>
            <max_speed>37.998337013956565</max_speed>
            <min_gas_flow>8.981854013171626e-05</min_gas_flow>
            <gas_efficiency>0.371</gas_efficiency>
            <battery_charge_watt_hours>291</battery_charge_watt_hours>
            <battery_discharge_watt_hours>214</battery_discharge_watt_hours>
            <max_steer>0.6458</max_steer>
            <flwheel_steering_p_gain>1e4</flwheel_steering_p_gain>
            <frwheel_steering_p_gain>1e4</frwheel_steering_p_gain>
            <flwheel_steering_i_gain>0</flwheel_steering_i_gain>
            <frwheel_steering_i_gain>0</frwheel_steering_i_gain>
            <flwheel_steering_d_gain>3e2</flwheel_steering_d_gain>
            <frwheel_steering_d_gain>3e2</frwheel_steering_d_gain>
        </plugin>
    </gazebo>
    <gazebo>
        <plugin name="joint_state_publisher" filename="libgazebo_ros_joint_state_publisher.so">
            <!-- <robotNamespace>/prius</robotNamespace> -->
            <jointName>rear_right_wheel_joint, rear_left_wheel_joint, front_right_wheel_joint, front_left_wheel_joint, front_right_steer_joint, front_left_steer_joint, steering_joint</jointName>
            <updateRate>100.0</updateRate>
            <alwaysOn>true</alwaysOn>
        </plugin>
    </gazebo>
    <gazebo>
        <plugin name="p3d" filename="libgazebo_ros_p3d.so">
            <!-- <robotNamespace>/prius</robotNamespace> -->
            <bodyName>base_link</bodyName>
            <topicName>base_pose_ground_truth</topicName>
            <frameName>map</frameName>
            <updateRate>100.0</updateRate>
        </plugin>
    </gazebo>
    <gazebo reference="velodyne">
        <sensor name="center_laser_sensor" type="ray">
            <ray>
                <scan>
                    <horizontal>
                        <samples>512</samples>
                        <resolution>1</resolution>
                        <min_angle>-3.14</min_angle>
                        <max_angle>3.14</max_angle>
                    </horizontal>
                    <vertical>
                        <samples>16</samples>
                        <min_angle>-0.1</min_angle>
                        <max_angle>-0.35</max_angle>
                    </vertical>
                </scan>
                <range>
                    <min>0.2</min>
                    <max>30</max>
                    <resolution>0.01</resolution>
                </range>
            </ray>
            <plugin name="center_laser" filename="libgazebo_ros_block_laser.so">
                <topicName>/prius/center_laser/scan</topicName>
                <frameName>velodyne</frameName>
            </plugin>
            <always_on>1</always_on>
            <update_rate>30</update_rate>
            <visualize>0</visualize>
        </sensor>
    </gazebo>
    <gazebo reference="front_camera_link">
        <sensor type="camera" name="front_camera_sensor">
            <update_rate>30.0</update_rate>
            <camera name="front_camera">
                <horizontal_fov>1.3962634</horizontal_fov>
                <image>
                    <width>800</width>
                    <height>800</height>
                    <format>R8G8B8</format>
                </image>
                <clip>
                    <near>0.02</near>
                    <far>300</far>
                </clip>
                <noise>
                    <type>gaussian</type>
                    <mean>0.0</mean>
                    <stddev>0.007</stddev>
                </noise>
            </camera>
            <plugin name="front_camera_controller" filename="libgazebo_ros_camera.so">
                <alwaysOn>false</alwaysOn>
                <updateRate>0.0</updateRate>
                <cameraName>/prius/front_camera</cameraName>
                <imageTopicName>image_raw</imageTopicName>
                <cameraInfoTopicName>/prius/front_camera_info</cameraInfoTopicName>
                <frameName>camera_link</frameName>
                <hackBaseline>0.07</hackBaseline>
                <distortionK1>0.0</distortionK1>
                <distortionK2>0.0</distortionK2>
                <distortionK3>0.0</distortionK3>
                <distortionT1>0.0</distortionT1>
                <distortionT2>0.0</distortionT2>
            </plugin>
        </sensor>
    </gazebo>
    <gazebo reference="left_camera_link">
        <sensor type="camera" name="left_camera_sensor">
            <update_rate>30.0</update_rate>
            <camera name="left_camera">
                <horizontal_fov>1.3962634</horizontal_fov>
                <image>
                    <width>800</width>
                    <height>800</height>
                    <format>R8G8B8</format>
                </image>
                <clip>
                    <near>0.02</near>
                    <far>300</far>
                </clip>
                <noise>
                    <type>gaussian</type>
                    <mean>0.0</mean>
                    <stddev>0.007</stddev>
                </noise>
            </camera>
            <plugin name="left_camera_controller" filename="libgazebo_ros_camera.so">
                <alwaysOn>false</alwaysOn>
                <updateRate>0.0</updateRate>
                <cameraName>/prius/left_camera</cameraName>
                <imageTopicName>image_raw</imageTopicName>
                <cameraInfoTopicName>/prius/left_camera_info</cameraInfoTopicName>
                <frameName>camera_link</frameName>
                <hackBaseline>0.07</hackBaseline>
                <distortionK1>0.0</distortionK1>
                <distortionK2>0.0</distortionK2>
                <distortionK3>0.0</distortionK3>
                <distortionT1>0.0</distortionT1>
                <distortionT2>0.0</distortionT2>
            </plugin>
        </sensor>
    </gazebo>
    <gazebo reference="right_camera_link">
        <sensor type="camera" name="right_camera_sensor">
            <update_rate>30.0</update_rate>
            <camera name="right_camera">
                <horizontal_fov>1.3962634</horizontal_fov>
                <image>
                    <width>800</width>
                    <height>800</height>
                    <format>R8G8B8</format>
                </image>
                <clip>
                    <near>0.02</near>
                    <far>300</far>
                </clip>
                <noise>
                    <type>gaussian</type>
                    <mean>0.0</mean>
                    <stddev>0.007</stddev>
                </noise>
            </camera>
            <plugin name="right_camera_controller" filename="libgazebo_ros_camera.so">
                <alwaysOn>false</alwaysOn>
                <updateRate>0.0</updateRate>
                <cameraName>/prius/right_camera</cameraName>
                <imageTopicName>image_raw</imageTopicName>
                <cameraInfoTopicName>/prius/right_camera_info</cameraInfoTopicName>
                <frameName>camera_link</frameName>
                <hackBaseline>0.07</hackBaseline>
                <distortionK1>0.0</distortionK1>
                <distortionK2>0.0</distortionK2>
                <distortionK3>0.0</distortionK3>
                <distortionT1>0.0</distortionT1>
                <distortionT2>0.0</distortionT2>
            </plugin>
        </sensor>
    </gazebo>
    <gazebo reference="front_center_right_sonar_link">
        <sensor name="front_center_right_sonar_sensor" type="ray">
            <ray>
                <scan>
                    <horizontal>
                        <samples>1</samples>
                        <resolution>1</resolution>
                        <min_angle>0</min_angle>
                        <max_angle>0</max_angle>
                    </horizontal>
                    <vertical>
                        <samples>1</samples>
                        <min_angle>0</min_angle>
                        <max_angle>0</max_angle>
                    </vertical>
                </scan>
                <range>
                    <min>0.2</min>
                    <max>5</max>
                    <resolution>0.1</resolution>
                </range>
            </ray>
            <plugin name="front_center_right_sonar_sensor" filename="libgazebo_ros_range.so">
                <topicName>/prius/front_sonar/center_right_range</topicName>
                <frameName>front_center_right_sonar_link</frameName>
            </plugin>
            <always_on>false</always_on>
            <update_rate>5</update_rate>
            <visualize>0</visualize>
        </sensor>
    </gazebo>
</robot>
